{
  "nbformat": 4,
  "nbformat_minor": 0,
  "metadata": {
    "colab": {
      "provenance": [],
      "gpuType": "T4"
    },
    "kernelspec": {
      "name": "python3",
      "display_name": "Python 3"
    },
    "language_info": {
      "name": "python"
    },
    "accelerator": "GPU"
  },
  "cells": [
    {
      "cell_type": "code",
      "execution_count": 1,
      "metadata": {
        "colab": {
          "base_uri": "https://localhost:8080/"
        },
        "id": "i_sVIW_XoHeJ",
        "outputId": "4bb4d641-68a7-476f-bfb7-e26f73d2c70c"
      },
      "outputs": [
        {
          "output_type": "stream",
          "name": "stdout",
          "text": [
            "\u001b[2K     \u001b[90m━━━━━━━━━━━━━━━━━━━━━━━━━━━━━━━━━━━━━━━━\u001b[0m \u001b[32m8.6/8.6 MB\u001b[0m \u001b[31m23.6 MB/s\u001b[0m eta \u001b[36m0:00:00\u001b[0m\n",
            "\u001b[2K     \u001b[90m━━━━━━━━━━━━━━━━━━━━━━━━━━━━━━━━━━━━━━━━\u001b[0m \u001b[32m207.3/207.3 kB\u001b[0m \u001b[31m11.9 MB/s\u001b[0m eta \u001b[36m0:00:00\u001b[0m\n",
            "\u001b[2K     \u001b[90m━━━━━━━━━━━━━━━━━━━━━━━━━━━━━━━━━━━━━━━━\u001b[0m \u001b[32m6.9/6.9 MB\u001b[0m \u001b[31m54.0 MB/s\u001b[0m eta \u001b[36m0:00:00\u001b[0m\n",
            "\u001b[2K     \u001b[90m━━━━━━━━━━━━━━━━━━━━━━━━━━━━━━━━━━━━━━━━\u001b[0m \u001b[32m83.0/83.0 kB\u001b[0m \u001b[31m6.1 MB/s\u001b[0m eta \u001b[36m0:00:00\u001b[0m\n",
            "\u001b[2K     \u001b[90m━━━━━━━━━━━━━━━━━━━━━━━━━━━━━━━━━━━━━━━━\u001b[0m \u001b[32m62.7/62.7 kB\u001b[0m \u001b[31m5.7 MB/s\u001b[0m eta \u001b[36m0:00:00\u001b[0m\n",
            "\u001b[?25h"
          ]
        }
      ],
      "source": [
        "!pip install streamlit -q"
      ]
    },
    {
      "cell_type": "code",
      "source": [
        "!wget -q -O - ipv4.icanhazip.com"
      ],
      "metadata": {
        "colab": {
          "base_uri": "https://localhost:8080/"
        },
        "id": "IGDMeN9QoPrZ",
        "outputId": "875de467-c28d-4de3-c7e2-2ff0bd0d4445"
      },
      "execution_count": 5,
      "outputs": [
        {
          "output_type": "stream",
          "name": "stdout",
          "text": [
            "35.204.59.236\n"
          ]
        }
      ]
    },
    {
      "cell_type": "code",
      "source": [
        "%%writefile fashion.py"
      ],
      "metadata": {
        "colab": {
          "base_uri": "https://localhost:8080/"
        },
        "id": "TqdsYNRDpZyM",
        "outputId": "ac1505d3-565d-4450-f912-18e76f144981"
      },
      "execution_count": 6,
      "outputs": [
        {
          "output_type": "stream",
          "name": "stdout",
          "text": [
            "Writing fashion.py\n"
          ]
        }
      ]
    },
    {
      "cell_type": "code",
      "source": [
        "!npm install localtunnel"
      ],
      "metadata": {
        "colab": {
          "base_uri": "https://localhost:8080/"
        },
        "id": "vOmUmwBMpxhP",
        "outputId": "98a92447-88f1-4054-bad6-72a1796b7935"
      },
      "execution_count": 7,
      "outputs": [
        {
          "output_type": "stream",
          "name": "stdout",
          "text": [
            "\u001b[K\u001b[?25h\u001b[37;40mnpm\u001b[0m \u001b[0m\u001b[30;43mWARN\u001b[0m \u001b[0m\u001b[35msaveError\u001b[0m ENOENT: no such file or directory, open '/content/package.json'\n",
            "\u001b[K\u001b[?25h\u001b[37;40mnpm\u001b[0m \u001b[0m\u001b[34;40mnotice\u001b[0m\u001b[35m\u001b[0m created a lockfile as package-lock.json. You should commit this file.\n",
            "\u001b[0m\u001b[37;40mnpm\u001b[0m \u001b[0m\u001b[30;43mWARN\u001b[0m \u001b[0m\u001b[35menoent\u001b[0m ENOENT: no such file or directory, open '/content/package.json'\n",
            "\u001b[0m\u001b[37;40mnpm\u001b[0m \u001b[0m\u001b[30;43mWARN\u001b[0m\u001b[35m\u001b[0m content No description\n",
            "\u001b[0m\u001b[37;40mnpm\u001b[0m \u001b[0m\u001b[30;43mWARN\u001b[0m\u001b[35m\u001b[0m content No repository field.\n",
            "\u001b[0m\u001b[37;40mnpm\u001b[0m \u001b[0m\u001b[30;43mWARN\u001b[0m\u001b[35m\u001b[0m content No README data\n",
            "\u001b[0m\u001b[37;40mnpm\u001b[0m \u001b[0m\u001b[30;43mWARN\u001b[0m\u001b[35m\u001b[0m content No license field.\n",
            "\u001b[0m\n",
            "+ localtunnel@2.0.2\n",
            "added 22 packages from 22 contributors and audited 22 packages in 2.433s\n",
            "\n",
            "3 packages are looking for funding\n",
            "  run `npm fund` for details\n",
            "\n",
            "found 1 \u001b[93mmoderate\u001b[0m severity vulnerability\n",
            "  run `npm audit fix` to fix them, or `npm audit` for details\n",
            "\u001b[K\u001b[?25h"
          ]
        }
      ]
    },
    {
      "cell_type": "code",
      "source": [
        "!streamlit run fashion.py & npx localtunnel --port 8501"
      ],
      "metadata": {
        "colab": {
          "base_uri": "https://localhost:8080/"
        },
        "id": "mDjHPS5Tp4zd",
        "outputId": "16c25c7c-6229-480d-fb8b-0acfed3a189a"
      },
      "execution_count": null,
      "outputs": [
        {
          "output_type": "stream",
          "name": "stdout",
          "text": [
            "\n",
            "Collecting usage statistics. To deactivate, set browser.gatherUsageStats to false.\n",
            "\u001b[0m\n",
            "\u001b[0m\n",
            "\u001b[34m\u001b[1m  You can now view your Streamlit app in your browser.\u001b[0m\n",
            "\u001b[0m\n",
            "\u001b[34m  Local URL: \u001b[0m\u001b[1mhttp://localhost:8501\u001b[0m\n",
            "\u001b[34m  Network URL: \u001b[0m\u001b[1mhttp://172.28.0.12:8501\u001b[0m\n",
            "\u001b[34m  External URL: \u001b[0m\u001b[1mhttp://35.204.59.236:8501\u001b[0m\n",
            "\u001b[0m\n",
            "\u001b[K\u001b[?25hnpx: installed 22 in 1.966s\n",
            "your url is: https://legal-keys-beg.loca.lt\n",
            "2024-07-03 12:56:02.224217: E external/local_xla/xla/stream_executor/cuda/cuda_dnn.cc:9261] Unable to register cuDNN factory: Attempting to register factory for plugin cuDNN when one has already been registered\n",
            "2024-07-03 12:56:02.224269: E external/local_xla/xla/stream_executor/cuda/cuda_fft.cc:607] Unable to register cuFFT factory: Attempting to register factory for plugin cuFFT when one has already been registered\n",
            "2024-07-03 12:56:02.225800: E external/local_xla/xla/stream_executor/cuda/cuda_blas.cc:1515] Unable to register cuBLAS factory: Attempting to register factory for plugin cuBLAS when one has already been registered\n",
            "2024-07-03 12:56:02.234995: I tensorflow/core/platform/cpu_feature_guard.cc:182] This TensorFlow binary is optimized to use available CPU instructions in performance-critical operations.\n",
            "To enable the following instructions: AVX2 AVX512F FMA, in other operations, rebuild TensorFlow with the appropriate compiler flags.\n",
            "2024-07-03 12:56:03.366876: W tensorflow/compiler/tf2tensorrt/utils/py_utils.cc:38] TF-TRT Warning: Could not find TensorRT\n",
            "2024-07-03 12:59:32.260 Uncaught app exception\n",
            "Traceback (most recent call last):\n",
            "  File \"/usr/local/lib/python3.10/dist-packages/streamlit/runtime/scriptrunner/script_runner.py\", line 589, in _run_script\n",
            "    exec(code, module.__dict__)\n",
            "  File \"/content/fashion.py\", line 5, in <module>\n",
            "    fr\n",
            "NameError: name 'fr' is not defined\n",
            "2024-07-03 13:00:01.917 Uncaught app exception\n",
            "Traceback (most recent call last):\n",
            "  File \"/usr/local/lib/python3.10/dist-packages/streamlit/runtime/scriptrunner/script_runner.py\", line 589, in _run_script\n",
            "    exec(code, module.__dict__)\n",
            "  File \"/content/fashion.py\", line 5, in <module>\n",
            "    from  PIL import Image,Imah\n",
            "ImportError: cannot import name 'Imah' from 'PIL' (/usr/local/lib/python3.10/dist-packages/PIL/__init__.py)\n",
            "2024-07-03 13:04:44.897 Uncaught app exception\n",
            "Traceback (most recent call last):\n",
            "  File \"/usr/local/lib/python3.10/dist-packages/streamlit/runtime/scriptrunner/script_runner.py\", line 589, in _run_script\n",
            "    exec(code, module.__dict__)\n",
            "  File \"/content/fashion.py\", line 14, in <module>\n",
            "    model=load_model()\n",
            "  File \"/content/fashion.py\", line 10, in load_model\n",
            "    model=tf.keras.model.load_model('/content/mnist_model.hdf5')\n",
            "  File \"/usr/local/lib/python3.10/dist-packages/tensorflow/python/util/lazy_loader.py\", line 171, in __getattr__\n",
            "    return getattr(module, item)\n",
            "AttributeError: module 'keras.api._v2.keras' has no attribute 'model'\n",
            "2024-07-03 13:05:16.735 Uncaught app exception\n",
            "Traceback (most recent call last):\n",
            "  File \"/usr/local/lib/python3.10/dist-packages/streamlit/runtime/scriptrunner/script_runner.py\", line 589, in _run_script\n",
            "    exec(code, module.__dict__)\n",
            "  File \"/content/fashion.py\", line 14, in <module>\n",
            "    model=load_model()\n",
            "  File \"/content/fashion.py\", line 10, in load_model\n",
            "    model=tf.keras.model.load_model('/content/mnist_model.hdf5')\n",
            "AttributeError: module 'keras.api._v2.keras' has no attribute 'model'\n",
            "2024-07-03 13:08:32.692003: I external/local_xla/xla/stream_executor/cuda/cuda_executor.cc:901] successful NUMA node read from SysFS had negative value (-1), but there must be at least one NUMA node, so returning NUMA node zero. See more at https://github.com/torvalds/linux/blob/v6.0/Documentation/ABI/testing/sysfs-bus-pci#L344-L355\n",
            "2024-07-03 13:08:33.181612: I external/local_xla/xla/stream_executor/cuda/cuda_executor.cc:901] successful NUMA node read from SysFS had negative value (-1), but there must be at least one NUMA node, so returning NUMA node zero. See more at https://github.com/torvalds/linux/blob/v6.0/Documentation/ABI/testing/sysfs-bus-pci#L344-L355\n",
            "2024-07-03 13:08:33.181948: I external/local_xla/xla/stream_executor/cuda/cuda_executor.cc:901] successful NUMA node read from SysFS had negative value (-1), but there must be at least one NUMA node, so returning NUMA node zero. See more at https://github.com/torvalds/linux/blob/v6.0/Documentation/ABI/testing/sysfs-bus-pci#L344-L355\n",
            "2024-07-03 13:08:33.183284: I external/local_xla/xla/stream_executor/cuda/cuda_executor.cc:901] successful NUMA node read from SysFS had negative value (-1), but there must be at least one NUMA node, so returning NUMA node zero. See more at https://github.com/torvalds/linux/blob/v6.0/Documentation/ABI/testing/sysfs-bus-pci#L344-L355\n",
            "2024-07-03 13:08:33.183535: I external/local_xla/xla/stream_executor/cuda/cuda_executor.cc:901] successful NUMA node read from SysFS had negative value (-1), but there must be at least one NUMA node, so returning NUMA node zero. See more at https://github.com/torvalds/linux/blob/v6.0/Documentation/ABI/testing/sysfs-bus-pci#L344-L355\n",
            "2024-07-03 13:08:33.183793: I external/local_xla/xla/stream_executor/cuda/cuda_executor.cc:901] successful NUMA node read from SysFS had negative value (-1), but there must be at least one NUMA node, so returning NUMA node zero. See more at https://github.com/torvalds/linux/blob/v6.0/Documentation/ABI/testing/sysfs-bus-pci#L344-L355\n",
            "2024-07-03 13:08:33.312356: I external/local_xla/xla/stream_executor/cuda/cuda_executor.cc:901] successful NUMA node read from SysFS had negative value (-1), but there must be at least one NUMA node, so returning NUMA node zero. See more at https://github.com/torvalds/linux/blob/v6.0/Documentation/ABI/testing/sysfs-bus-pci#L344-L355\n",
            "2024-07-03 13:08:33.312641: I external/local_xla/xla/stream_executor/cuda/cuda_executor.cc:901] successful NUMA node read from SysFS had negative value (-1), but there must be at least one NUMA node, so returning NUMA node zero. See more at https://github.com/torvalds/linux/blob/v6.0/Documentation/ABI/testing/sysfs-bus-pci#L344-L355\n",
            "2024-07-03 13:08:33.312824: W tensorflow/core/common_runtime/gpu/gpu_bfc_allocator.cc:47] Overriding orig_value setting because the TF_FORCE_GPU_ALLOW_GROWTH environment variable is set. Original config value was 0.\n",
            "2024-07-03 13:08:33.312927: I external/local_xla/xla/stream_executor/cuda/cuda_executor.cc:901] successful NUMA node read from SysFS had negative value (-1), but there must be at least one NUMA node, so returning NUMA node zero. See more at https://github.com/torvalds/linux/blob/v6.0/Documentation/ABI/testing/sysfs-bus-pci#L344-L355\n",
            "2024-07-03 13:08:33.313084: I tensorflow/core/common_runtime/gpu/gpu_device.cc:1929] Created device /job:localhost/replica:0/task:0/device:GPU:0 with 13949 MB memory:  -> device: 0, name: Tesla T4, pci bus id: 0000:00:04.0, compute capability: 7.5\n",
            "2024-07-03 13:18:50.646 Uncaught app exception\n",
            "Traceback (most recent call last):\n",
            "  File \"/usr/local/lib/python3.10/dist-packages/streamlit/runtime/scriptrunner/script_runner.py\", line 589, in _run_script\n",
            "    exec(code, module.__dict__)\n",
            "  File \"/content/fashion.py\", line 26, in <module>\n",
            "    files=st.file_uploader(type=['jpg','png'])\n",
            "  File \"/usr/local/lib/python3.10/dist-packages/streamlit/runtime/metrics_util.py\", line 408, in wrapped_func\n",
            "    result = non_optional_func(*args, **kwargs)\n",
            "TypeError: FileUploaderMixin.file_uploader() missing 1 required positional argument: 'label'\n",
            "2024-07-03 13:19:05.496 `label` got an empty value. This is discouraged for accessibility reasons and may be disallowed in the future by raising an exception. Please provide a non-empty label and hide it with label_visibility if needed.\n",
            "2024-07-03 13:27:03.971 `label` got an empty value. This is discouraged for accessibility reasons and may be disallowed in the future by raising an exception. Please provide a non-empty label and hide it with label_visibility if needed.\n",
            "2024-07-03 13:27:03.971 Uncaught app exception\n",
            "Traceback (most recent call last):\n",
            "  File \"/usr/local/lib/python3.10/dist-packages/streamlit/runtime/scriptrunner/script_runner.py\", line 589, in _run_script\n",
            "    exec(code, module.__dict__)\n",
            "  File \"/content/fashion.py\", line 28, in <module>\n",
            "    if file is None:\n",
            "NameError: name 'file' is not defined\n",
            "2024-07-03 13:28:03.504 `label` got an empty value. This is discouraged for accessibility reasons and may be disallowed in the future by raising an exception. Please provide a non-empty label and hide it with label_visibility if needed.\n",
            "2024-07-03 13:28:33.572 `label` got an empty value. This is discouraged for accessibility reasons and may be disallowed in the future by raising an exception. Please provide a non-empty label and hide it with label_visibility if needed.\n",
            "2024-07-03 13:29:04.080 `label` got an empty value. This is discouraged for accessibility reasons and may be disallowed in the future by raising an exception. Please provide a non-empty label and hide it with label_visibility if needed.\n",
            "2024-07-03 13:29:19.746 `label` got an empty value. This is discouraged for accessibility reasons and may be disallowed in the future by raising an exception. Please provide a non-empty label and hide it with label_visibility if needed.\n",
            "2024-07-03 13:29:51.201 `label` got an empty value. This is discouraged for accessibility reasons and may be disallowed in the future by raising an exception. Please provide a non-empty label and hide it with label_visibility if needed.\n",
            "2024-07-03 13:30:00.479 `label` got an empty value. This is discouraged for accessibility reasons and may be disallowed in the future by raising an exception. Please provide a non-empty label and hide it with label_visibility if needed.\n",
            "/content/fashion.py:18: DeprecationWarning: ANTIALIAS is deprecated and will be removed in Pillow 10 (2023-07-01). Use LANCZOS or Resampling.LANCZOS instead.\n",
            "  image=ImageOps.fit(image_data,size,Image.ANTIALIAS)\n",
            "2024-07-03 13:30:00.650 Uncaught app exception\n",
            "Traceback (most recent call last):\n",
            "  File \"/usr/local/lib/python3.10/dist-packages/streamlit/runtime/scriptrunner/script_runner.py\", line 589, in _run_script\n",
            "    exec(code, module.__dict__)\n",
            "  File \"/content/fashion.py\", line 33, in <module>\n",
            "    predictions=predict(image,model)\n",
            "  File \"/content/fashion.py\", line 22, in predict\n",
            "    prediction=model.predict(img_reshape)\n",
            "  File \"/usr/local/lib/python3.10/dist-packages/keras/src/utils/traceback_utils.py\", line 70, in error_handler\n",
            "    raise e.with_traceback(filtered_tb) from None\n",
            "  File \"/tmp/__autograph_generated_filefnm75z2s.py\", line 15, in tf__predict_function\n",
            "    retval_ = ag__.converted_call(ag__.ld(step_function), (ag__.ld(self), ag__.ld(iterator)), None, fscope)\n",
            "ValueError: in user code:\n",
            "\n",
            "    File \"/usr/local/lib/python3.10/dist-packages/keras/src/engine/training.py\", line 2440, in predict_function  *\n",
            "        return step_function(self, iterator)\n",
            "    File \"/usr/local/lib/python3.10/dist-packages/keras/src/engine/training.py\", line 2425, in step_function  **\n",
            "        outputs = model.distribute_strategy.run(run_step, args=(data,))\n",
            "    File \"/usr/local/lib/python3.10/dist-packages/keras/src/engine/training.py\", line 2413, in run_step  **\n",
            "        outputs = model.predict_step(data)\n",
            "    File \"/usr/local/lib/python3.10/dist-packages/keras/src/engine/training.py\", line 2381, in predict_step\n",
            "        return self(x, training=False)\n",
            "    File \"/usr/local/lib/python3.10/dist-packages/keras/src/utils/traceback_utils.py\", line 70, in error_handler\n",
            "        raise e.with_traceback(filtered_tb) from None\n",
            "    File \"/usr/local/lib/python3.10/dist-packages/keras/src/engine/input_spec.py\", line 235, in assert_input_compatibility\n",
            "        raise ValueError(\n",
            "\n",
            "    ValueError: Exception encountered when calling layer 'model' (type Functional).\n",
            "    \n",
            "    Input 0 of layer \"lstm\" is incompatible with the layer: expected ndim=3, found ndim=4. Full shape received: (None, 28, 28, 3)\n",
            "    \n",
            "    Call arguments received by layer 'model' (type Functional):\n",
            "      • inputs=tf.Tensor(shape=(None, 28, 28, 3), dtype=uint8)\n",
            "      • training=False\n",
            "      • mask=None\n",
            "\n",
            "2024-07-03 13:34:19.008 `label` got an empty value. This is discouraged for accessibility reasons and may be disallowed in the future by raising an exception. Please provide a non-empty label and hide it with label_visibility if needed.\n",
            "/content/fashion.py:18: DeprecationWarning: ANTIALIAS is deprecated and will be removed in Pillow 10 (2023-07-01). Use LANCZOS or Resampling.LANCZOS instead.\n",
            "  image=ImageOps.fit(image_data,size,Image.ANTIALIAS)\n",
            "2024-07-03 13:34:19.100 Uncaught app exception\n",
            "Traceback (most recent call last):\n",
            "  File \"/usr/local/lib/python3.10/dist-packages/streamlit/runtime/scriptrunner/script_runner.py\", line 589, in _run_script\n",
            "    exec(code, module.__dict__)\n",
            "  File \"/content/fashion.py\", line 33, in <module>\n",
            "    predictions=predict(image,model)\n",
            "  File \"/content/fashion.py\", line 22, in predict\n",
            "    prediction=model.predict(img_reshape)\n",
            "  File \"/usr/local/lib/python3.10/dist-packages/keras/src/utils/traceback_utils.py\", line 70, in error_handler\n",
            "    raise e.with_traceback(filtered_tb) from None\n",
            "  File \"/tmp/__autograph_generated_filefnm75z2s.py\", line 15, in tf__predict_function\n",
            "    retval_ = ag__.converted_call(ag__.ld(step_function), (ag__.ld(self), ag__.ld(iterator)), None, fscope)\n",
            "ValueError: in user code:\n",
            "\n",
            "    File \"/usr/local/lib/python3.10/dist-packages/keras/src/engine/training.py\", line 2440, in predict_function  *\n",
            "        return step_function(self, iterator)\n",
            "    File \"/usr/local/lib/python3.10/dist-packages/keras/src/engine/training.py\", line 2425, in step_function  **\n",
            "        outputs = model.distribute_strategy.run(run_step, args=(data,))\n",
            "    File \"/usr/local/lib/python3.10/dist-packages/keras/src/engine/training.py\", line 2413, in run_step  **\n",
            "        outputs = model.predict_step(data)\n",
            "    File \"/usr/local/lib/python3.10/dist-packages/keras/src/engine/training.py\", line 2381, in predict_step\n",
            "        return self(x, training=False)\n",
            "    File \"/usr/local/lib/python3.10/dist-packages/keras/src/utils/traceback_utils.py\", line 70, in error_handler\n",
            "        raise e.with_traceback(filtered_tb) from None\n",
            "    File \"/usr/local/lib/python3.10/dist-packages/keras/src/engine/input_spec.py\", line 235, in assert_input_compatibility\n",
            "        raise ValueError(\n",
            "\n",
            "    ValueError: Exception encountered when calling layer 'model' (type Functional).\n",
            "    \n",
            "    Input 0 of layer \"lstm\" is incompatible with the layer: expected ndim=3, found ndim=4. Full shape received: (None, 28, 28, 3)\n",
            "    \n",
            "    Call arguments received by layer 'model' (type Functional):\n",
            "      • inputs=tf.Tensor(shape=(None, 28, 28, 3), dtype=uint8)\n",
            "      • training=False\n",
            "      • mask=None\n",
            "\n",
            "2024-07-03 13:38:06.884 `label` got an empty value. This is discouraged for accessibility reasons and may be disallowed in the future by raising an exception. Please provide a non-empty label and hide it with label_visibility if needed.\n",
            "/content/fashion.py:18: DeprecationWarning: ANTIALIAS is deprecated and will be removed in Pillow 10 (2023-07-01). Use LANCZOS or Resampling.LANCZOS instead.\n",
            "  image=ImageOps.fit(image_data,size,Image.ANTIALIAS)\n",
            "2024-07-03 13:38:06.984 Uncaught app exception\n",
            "Traceback (most recent call last):\n",
            "  File \"/usr/local/lib/python3.10/dist-packages/streamlit/runtime/scriptrunner/script_runner.py\", line 589, in _run_script\n",
            "    exec(code, module.__dict__)\n",
            "  File \"/content/fashion.py\", line 33, in <module>\n",
            "    predictions=predict(image,model)\n",
            "  File \"/content/fashion.py\", line 22, in predict\n",
            "    prediction=model.predict(img_reshape)\n",
            "  File \"/usr/local/lib/python3.10/dist-packages/keras/src/utils/traceback_utils.py\", line 70, in error_handler\n",
            "    raise e.with_traceback(filtered_tb) from None\n",
            "  File \"/tmp/__autograph_generated_filefnm75z2s.py\", line 15, in tf__predict_function\n",
            "    retval_ = ag__.converted_call(ag__.ld(step_function), (ag__.ld(self), ag__.ld(iterator)), None, fscope)\n",
            "ValueError: in user code:\n",
            "\n",
            "    File \"/usr/local/lib/python3.10/dist-packages/keras/src/engine/training.py\", line 2440, in predict_function  *\n",
            "        return step_function(self, iterator)\n",
            "    File \"/usr/local/lib/python3.10/dist-packages/keras/src/engine/training.py\", line 2425, in step_function  **\n",
            "        outputs = model.distribute_strategy.run(run_step, args=(data,))\n",
            "    File \"/usr/local/lib/python3.10/dist-packages/keras/src/engine/training.py\", line 2413, in run_step  **\n",
            "        outputs = model.predict_step(data)\n",
            "    File \"/usr/local/lib/python3.10/dist-packages/keras/src/engine/training.py\", line 2381, in predict_step\n",
            "        return self(x, training=False)\n",
            "    File \"/usr/local/lib/python3.10/dist-packages/keras/src/utils/traceback_utils.py\", line 70, in error_handler\n",
            "        raise e.with_traceback(filtered_tb) from None\n",
            "    File \"/usr/local/lib/python3.10/dist-packages/keras/src/engine/input_spec.py\", line 235, in assert_input_compatibility\n",
            "        raise ValueError(\n",
            "\n",
            "    ValueError: Exception encountered when calling layer 'model' (type Functional).\n",
            "    \n",
            "    Input 0 of layer \"lstm\" is incompatible with the layer: expected ndim=3, found ndim=4. Full shape received: (None, 28, 28, 3)\n",
            "    \n",
            "    Call arguments received by layer 'model' (type Functional):\n",
            "      • inputs=tf.Tensor(shape=(None, 28, 28, 3), dtype=uint8)\n",
            "      • training=False\n",
            "      • mask=None\n",
            "\n",
            "2024-07-03 13:38:43.321 `label` got an empty value. This is discouraged for accessibility reasons and may be disallowed in the future by raising an exception. Please provide a non-empty label and hide it with label_visibility if needed.\n",
            "/content/fashion.py:18: DeprecationWarning: ANTIALIAS is deprecated and will be removed in Pillow 10 (2023-07-01). Use LANCZOS or Resampling.LANCZOS instead.\n",
            "  image=ImageOps.fit(image_data,size,Image.ANTIALIAS)\n",
            "2024-07-03 13:38:43.418 Uncaught app exception\n",
            "Traceback (most recent call last):\n",
            "  File \"/usr/local/lib/python3.10/dist-packages/streamlit/runtime/scriptrunner/script_runner.py\", line 589, in _run_script\n",
            "    exec(code, module.__dict__)\n",
            "  File \"/content/fashion.py\", line 33, in <module>\n",
            "    predictions=predict(image,model)\n",
            "  File \"/content/fashion.py\", line 22, in predict\n",
            "    prediction=model.predict(img_reshape)\n",
            "  File \"/usr/local/lib/python3.10/dist-packages/keras/src/utils/traceback_utils.py\", line 70, in error_handler\n",
            "    raise e.with_traceback(filtered_tb) from None\n",
            "  File \"/tmp/__autograph_generated_filefnm75z2s.py\", line 15, in tf__predict_function\n",
            "    retval_ = ag__.converted_call(ag__.ld(step_function), (ag__.ld(self), ag__.ld(iterator)), None, fscope)\n",
            "ValueError: in user code:\n",
            "\n",
            "    File \"/usr/local/lib/python3.10/dist-packages/keras/src/engine/training.py\", line 2440, in predict_function  *\n",
            "        return step_function(self, iterator)\n",
            "    File \"/usr/local/lib/python3.10/dist-packages/keras/src/engine/training.py\", line 2425, in step_function  **\n",
            "        outputs = model.distribute_strategy.run(run_step, args=(data,))\n",
            "    File \"/usr/local/lib/python3.10/dist-packages/keras/src/engine/training.py\", line 2413, in run_step  **\n",
            "        outputs = model.predict_step(data)\n",
            "    File \"/usr/local/lib/python3.10/dist-packages/keras/src/engine/training.py\", line 2381, in predict_step\n",
            "        return self(x, training=False)\n",
            "    File \"/usr/local/lib/python3.10/dist-packages/keras/src/utils/traceback_utils.py\", line 70, in error_handler\n",
            "        raise e.with_traceback(filtered_tb) from None\n",
            "    File \"/usr/local/lib/python3.10/dist-packages/keras/src/engine/input_spec.py\", line 235, in assert_input_compatibility\n",
            "        raise ValueError(\n",
            "\n",
            "    ValueError: Exception encountered when calling layer 'model' (type Functional).\n",
            "    \n",
            "    Input 0 of layer \"lstm\" is incompatible with the layer: expected ndim=3, found ndim=4. Full shape received: (None, 28, 28, 3)\n",
            "    \n",
            "    Call arguments received by layer 'model' (type Functional):\n",
            "      • inputs=tf.Tensor(shape=(None, 28, 28, 3), dtype=uint8)\n",
            "      • training=False\n",
            "      • mask=None\n",
            "\n",
            "2024-07-03 13:38:51.360 `label` got an empty value. This is discouraged for accessibility reasons and may be disallowed in the future by raising an exception. Please provide a non-empty label and hide it with label_visibility if needed.\n",
            "/content/fashion.py:18: DeprecationWarning: ANTIALIAS is deprecated and will be removed in Pillow 10 (2023-07-01). Use LANCZOS or Resampling.LANCZOS instead.\n",
            "  image=ImageOps.fit(image_data,size,Image.ANTIALIAS)\n",
            "2024-07-03 13:38:51.491 Uncaught app exception\n",
            "Traceback (most recent call last):\n",
            "  File \"/usr/local/lib/python3.10/dist-packages/streamlit/runtime/scriptrunner/script_runner.py\", line 589, in _run_script\n",
            "    exec(code, module.__dict__)\n",
            "  File \"/content/fashion.py\", line 33, in <module>\n",
            "    predictions=predict(image,model)\n",
            "  File \"/content/fashion.py\", line 22, in predict\n",
            "    prediction=model.predict(img_reshape)\n",
            "  File \"/usr/local/lib/python3.10/dist-packages/keras/src/utils/traceback_utils.py\", line 70, in error_handler\n",
            "    raise e.with_traceback(filtered_tb) from None\n",
            "  File \"/tmp/__autograph_generated_filefnm75z2s.py\", line 15, in tf__predict_function\n",
            "    retval_ = ag__.converted_call(ag__.ld(step_function), (ag__.ld(self), ag__.ld(iterator)), None, fscope)\n",
            "ValueError: in user code:\n",
            "\n",
            "    File \"/usr/local/lib/python3.10/dist-packages/keras/src/engine/training.py\", line 2440, in predict_function  *\n",
            "        return step_function(self, iterator)\n",
            "    File \"/usr/local/lib/python3.10/dist-packages/keras/src/engine/training.py\", line 2425, in step_function  **\n",
            "        outputs = model.distribute_strategy.run(run_step, args=(data,))\n",
            "    File \"/usr/local/lib/python3.10/dist-packages/keras/src/engine/training.py\", line 2413, in run_step  **\n",
            "        outputs = model.predict_step(data)\n",
            "    File \"/usr/local/lib/python3.10/dist-packages/keras/src/engine/training.py\", line 2381, in predict_step\n",
            "        return self(x, training=False)\n",
            "    File \"/usr/local/lib/python3.10/dist-packages/keras/src/utils/traceback_utils.py\", line 70, in error_handler\n",
            "        raise e.with_traceback(filtered_tb) from None\n",
            "    File \"/usr/local/lib/python3.10/dist-packages/keras/src/engine/input_spec.py\", line 235, in assert_input_compatibility\n",
            "        raise ValueError(\n",
            "\n",
            "    ValueError: Exception encountered when calling layer 'model' (type Functional).\n",
            "    \n",
            "    Input 0 of layer \"lstm\" is incompatible with the layer: expected ndim=3, found ndim=4. Full shape received: (None, 28, 28, 3)\n",
            "    \n",
            "    Call arguments received by layer 'model' (type Functional):\n",
            "      • inputs=tf.Tensor(shape=(None, 28, 28, 3), dtype=uint8)\n",
            "      • training=False\n",
            "      • mask=None\n",
            "\n",
            "2024-07-03 13:38:57.606 `label` got an empty value. This is discouraged for accessibility reasons and may be disallowed in the future by raising an exception. Please provide a non-empty label and hide it with label_visibility if needed.\n",
            "/content/fashion.py:18: DeprecationWarning: ANTIALIAS is deprecated and will be removed in Pillow 10 (2023-07-01). Use LANCZOS or Resampling.LANCZOS instead.\n",
            "  image=ImageOps.fit(image_data,size,Image.ANTIALIAS)\n",
            "2024-07-03 13:38:57.705 Uncaught app exception\n",
            "Traceback (most recent call last):\n",
            "  File \"/usr/local/lib/python3.10/dist-packages/streamlit/runtime/scriptrunner/script_runner.py\", line 589, in _run_script\n",
            "    exec(code, module.__dict__)\n",
            "  File \"/content/fashion.py\", line 33, in <module>\n",
            "    predictions=predict(image,model)\n",
            "  File \"/content/fashion.py\", line 22, in predict\n",
            "    prediction=model.predict(img_reshape)\n",
            "  File \"/usr/local/lib/python3.10/dist-packages/keras/src/utils/traceback_utils.py\", line 70, in error_handler\n",
            "    raise e.with_traceback(filtered_tb) from None\n",
            "  File \"/tmp/__autograph_generated_filefnm75z2s.py\", line 15, in tf__predict_function\n",
            "    retval_ = ag__.converted_call(ag__.ld(step_function), (ag__.ld(self), ag__.ld(iterator)), None, fscope)\n",
            "ValueError: in user code:\n",
            "\n",
            "    File \"/usr/local/lib/python3.10/dist-packages/keras/src/engine/training.py\", line 2440, in predict_function  *\n",
            "        return step_function(self, iterator)\n",
            "    File \"/usr/local/lib/python3.10/dist-packages/keras/src/engine/training.py\", line 2425, in step_function  **\n",
            "        outputs = model.distribute_strategy.run(run_step, args=(data,))\n",
            "    File \"/usr/local/lib/python3.10/dist-packages/keras/src/engine/training.py\", line 2413, in run_step  **\n",
            "        outputs = model.predict_step(data)\n",
            "    File \"/usr/local/lib/python3.10/dist-packages/keras/src/engine/training.py\", line 2381, in predict_step\n",
            "        return self(x, training=False)\n",
            "    File \"/usr/local/lib/python3.10/dist-packages/keras/src/utils/traceback_utils.py\", line 70, in error_handler\n",
            "        raise e.with_traceback(filtered_tb) from None\n",
            "    File \"/usr/local/lib/python3.10/dist-packages/keras/src/engine/input_spec.py\", line 235, in assert_input_compatibility\n",
            "        raise ValueError(\n",
            "\n",
            "    ValueError: Exception encountered when calling layer 'model' (type Functional).\n",
            "    \n",
            "    Input 0 of layer \"lstm\" is incompatible with the layer: expected ndim=3, found ndim=4. Full shape received: (None, 28, 28, 3)\n",
            "    \n",
            "    Call arguments received by layer 'model' (type Functional):\n",
            "      • inputs=tf.Tensor(shape=(None, 28, 28, 3), dtype=uint8)\n",
            "      • training=False\n",
            "      • mask=None\n",
            "\n",
            "2024-07-03 13:39:18.303 `label` got an empty value. This is discouraged for accessibility reasons and may be disallowed in the future by raising an exception. Please provide a non-empty label and hide it with label_visibility if needed.\n",
            "/content/fashion.py:18: DeprecationWarning: ANTIALIAS is deprecated and will be removed in Pillow 10 (2023-07-01). Use LANCZOS or Resampling.LANCZOS instead.\n",
            "  image=ImageOps.fit(image_data,size,Image.ANTIALIAS)\n",
            "2024-07-03 13:39:18.399 Uncaught app exception\n",
            "Traceback (most recent call last):\n",
            "  File \"/usr/local/lib/python3.10/dist-packages/streamlit/runtime/scriptrunner/script_runner.py\", line 589, in _run_script\n",
            "    exec(code, module.__dict__)\n",
            "  File \"/content/fashion.py\", line 33, in <module>\n",
            "    predictions=predict(image,model)\n",
            "  File \"/content/fashion.py\", line 22, in predict\n",
            "    prediction=model.predict(img_reshape)\n",
            "  File \"/usr/local/lib/python3.10/dist-packages/keras/src/utils/traceback_utils.py\", line 70, in error_handler\n",
            "    raise e.with_traceback(filtered_tb) from None\n",
            "  File \"/tmp/__autograph_generated_filefnm75z2s.py\", line 15, in tf__predict_function\n",
            "    retval_ = ag__.converted_call(ag__.ld(step_function), (ag__.ld(self), ag__.ld(iterator)), None, fscope)\n",
            "ValueError: in user code:\n",
            "\n",
            "    File \"/usr/local/lib/python3.10/dist-packages/keras/src/engine/training.py\", line 2440, in predict_function  *\n",
            "        return step_function(self, iterator)\n",
            "    File \"/usr/local/lib/python3.10/dist-packages/keras/src/engine/training.py\", line 2425, in step_function  **\n",
            "        outputs = model.distribute_strategy.run(run_step, args=(data,))\n",
            "    File \"/usr/local/lib/python3.10/dist-packages/keras/src/engine/training.py\", line 2413, in run_step  **\n",
            "        outputs = model.predict_step(data)\n",
            "    File \"/usr/local/lib/python3.10/dist-packages/keras/src/engine/training.py\", line 2381, in predict_step\n",
            "        return self(x, training=False)\n",
            "    File \"/usr/local/lib/python3.10/dist-packages/keras/src/utils/traceback_utils.py\", line 70, in error_handler\n",
            "        raise e.with_traceback(filtered_tb) from None\n",
            "    File \"/usr/local/lib/python3.10/dist-packages/keras/src/engine/input_spec.py\", line 235, in assert_input_compatibility\n",
            "        raise ValueError(\n",
            "\n",
            "    ValueError: Exception encountered when calling layer 'model' (type Functional).\n",
            "    \n",
            "    Input 0 of layer \"lstm\" is incompatible with the layer: expected ndim=3, found ndim=4. Full shape received: (None, 28, 28, 3)\n",
            "    \n",
            "    Call arguments received by layer 'model' (type Functional):\n",
            "      • inputs=tf.Tensor(shape=(None, 28, 28, 3), dtype=uint8)\n",
            "      • training=False\n",
            "      • mask=None\n",
            "\n",
            "2024-07-03 13:41:33.599 `label` got an empty value. This is discouraged for accessibility reasons and may be disallowed in the future by raising an exception. Please provide a non-empty label and hide it with label_visibility if needed.\n",
            "/content/fashion.py:18: DeprecationWarning: ANTIALIAS is deprecated and will be removed in Pillow 10 (2023-07-01). Use LANCZOS or Resampling.LANCZOS instead.\n",
            "  image=ImageOps.fit(image_data,size,Image.ANTIALIAS)\n",
            "2024-07-03 13:41:33.746 Uncaught app exception\n",
            "Traceback (most recent call last):\n",
            "  File \"/usr/local/lib/python3.10/dist-packages/streamlit/runtime/scriptrunner/script_runner.py\", line 589, in _run_script\n",
            "    exec(code, module.__dict__)\n",
            "  File \"/content/fashion.py\", line 33, in <module>\n",
            "    predictions=predict(image,model)\n",
            "  File \"/content/fashion.py\", line 22, in predict\n",
            "    prediction=model.predict(img_reshape)\n",
            "  File \"/usr/local/lib/python3.10/dist-packages/keras/src/utils/traceback_utils.py\", line 70, in error_handler\n",
            "    raise e.with_traceback(filtered_tb) from None\n",
            "  File \"/tmp/__autograph_generated_filefnm75z2s.py\", line 15, in tf__predict_function\n",
            "    retval_ = ag__.converted_call(ag__.ld(step_function), (ag__.ld(self), ag__.ld(iterator)), None, fscope)\n",
            "ValueError: in user code:\n",
            "\n",
            "    File \"/usr/local/lib/python3.10/dist-packages/keras/src/engine/training.py\", line 2440, in predict_function  *\n",
            "        return step_function(self, iterator)\n",
            "    File \"/usr/local/lib/python3.10/dist-packages/keras/src/engine/training.py\", line 2425, in step_function  **\n",
            "        outputs = model.distribute_strategy.run(run_step, args=(data,))\n",
            "    File \"/usr/local/lib/python3.10/dist-packages/keras/src/engine/training.py\", line 2413, in run_step  **\n",
            "        outputs = model.predict_step(data)\n",
            "    File \"/usr/local/lib/python3.10/dist-packages/keras/src/engine/training.py\", line 2381, in predict_step\n",
            "        return self(x, training=False)\n",
            "    File \"/usr/local/lib/python3.10/dist-packages/keras/src/utils/traceback_utils.py\", line 70, in error_handler\n",
            "        raise e.with_traceback(filtered_tb) from None\n",
            "    File \"/usr/local/lib/python3.10/dist-packages/keras/src/engine/input_spec.py\", line 235, in assert_input_compatibility\n",
            "        raise ValueError(\n",
            "\n",
            "    ValueError: Exception encountered when calling layer 'model' (type Functional).\n",
            "    \n",
            "    Input 0 of layer \"lstm\" is incompatible with the layer: expected ndim=3, found ndim=4. Full shape received: (None, 28, 28, 3)\n",
            "    \n",
            "    Call arguments received by layer 'model' (type Functional):\n",
            "      • inputs=tf.Tensor(shape=(None, 28, 28, 3), dtype=uint8)\n",
            "      • training=False\n",
            "      • mask=None\n",
            "\n",
            "2024-07-03 13:41:49.768 `label` got an empty value. This is discouraged for accessibility reasons and may be disallowed in the future by raising an exception. Please provide a non-empty label and hide it with label_visibility if needed.\n",
            "/content/fashion.py:18: DeprecationWarning: ANTIALIAS is deprecated and will be removed in Pillow 10 (2023-07-01). Use LANCZOS or Resampling.LANCZOS instead.\n",
            "  image=ImageOps.fit(image_data,size,Image.ANTIALIAS)\n",
            "2024-07-03 13:41:49.869 Uncaught app exception\n",
            "Traceback (most recent call last):\n",
            "  File \"/usr/local/lib/python3.10/dist-packages/streamlit/runtime/scriptrunner/script_runner.py\", line 589, in _run_script\n",
            "    exec(code, module.__dict__)\n",
            "  File \"/content/fashion.py\", line 33, in <module>\n",
            "    predictions=predict(image,model)\n",
            "  File \"/content/fashion.py\", line 22, in predict\n",
            "    prediction=model.predict(img_reshape)\n",
            "  File \"/usr/local/lib/python3.10/dist-packages/keras/src/utils/traceback_utils.py\", line 70, in error_handler\n",
            "    raise e.with_traceback(filtered_tb) from None\n",
            "  File \"/tmp/__autograph_generated_filefnm75z2s.py\", line 15, in tf__predict_function\n",
            "    retval_ = ag__.converted_call(ag__.ld(step_function), (ag__.ld(self), ag__.ld(iterator)), None, fscope)\n",
            "ValueError: in user code:\n",
            "\n",
            "    File \"/usr/local/lib/python3.10/dist-packages/keras/src/engine/training.py\", line 2440, in predict_function  *\n",
            "        return step_function(self, iterator)\n",
            "    File \"/usr/local/lib/python3.10/dist-packages/keras/src/engine/training.py\", line 2425, in step_function  **\n",
            "        outputs = model.distribute_strategy.run(run_step, args=(data,))\n",
            "    File \"/usr/local/lib/python3.10/dist-packages/keras/src/engine/training.py\", line 2413, in run_step  **\n",
            "        outputs = model.predict_step(data)\n",
            "    File \"/usr/local/lib/python3.10/dist-packages/keras/src/engine/training.py\", line 2381, in predict_step\n",
            "        return self(x, training=False)\n",
            "    File \"/usr/local/lib/python3.10/dist-packages/keras/src/utils/traceback_utils.py\", line 70, in error_handler\n",
            "        raise e.with_traceback(filtered_tb) from None\n",
            "    File \"/usr/local/lib/python3.10/dist-packages/keras/src/engine/input_spec.py\", line 235, in assert_input_compatibility\n",
            "        raise ValueError(\n",
            "\n",
            "    ValueError: Exception encountered when calling layer 'model' (type Functional).\n",
            "    \n",
            "    Input 0 of layer \"lstm\" is incompatible with the layer: expected ndim=3, found ndim=4. Full shape received: (None, 28, 28, 3)\n",
            "    \n",
            "    Call arguments received by layer 'model' (type Functional):\n",
            "      • inputs=tf.Tensor(shape=(None, 28, 28, 3), dtype=uint8)\n",
            "      • training=False\n",
            "      • mask=None\n",
            "\n",
            "2024-07-03 13:43:03.597 `label` got an empty value. This is discouraged for accessibility reasons and may be disallowed in the future by raising an exception. Please provide a non-empty label and hide it with label_visibility if needed.\n",
            "/content/fashion.py:18: DeprecationWarning: ANTIALIAS is deprecated and will be removed in Pillow 10 (2023-07-01). Use LANCZOS or Resampling.LANCZOS instead.\n",
            "  image=ImageOps.fit(image_data,size,Image.ANTIALIAS)\n",
            "2024-07-03 13:43:03.692 Uncaught app exception\n",
            "Traceback (most recent call last):\n",
            "  File \"/usr/local/lib/python3.10/dist-packages/streamlit/runtime/scriptrunner/script_runner.py\", line 589, in _run_script\n",
            "    exec(code, module.__dict__)\n",
            "  File \"/content/fashion.py\", line 33, in <module>\n",
            "    predictions=predict(image,model)\n",
            "  File \"/content/fashion.py\", line 22, in predict\n",
            "    prediction=model.predict(img_reshape)\n",
            "  File \"/usr/local/lib/python3.10/dist-packages/keras/src/utils/traceback_utils.py\", line 70, in error_handler\n",
            "    raise e.with_traceback(filtered_tb) from None\n",
            "  File \"/tmp/__autograph_generated_filefnm75z2s.py\", line 15, in tf__predict_function\n",
            "    retval_ = ag__.converted_call(ag__.ld(step_function), (ag__.ld(self), ag__.ld(iterator)), None, fscope)\n",
            "ValueError: in user code:\n",
            "\n",
            "    File \"/usr/local/lib/python3.10/dist-packages/keras/src/engine/training.py\", line 2440, in predict_function  *\n",
            "        return step_function(self, iterator)\n",
            "    File \"/usr/local/lib/python3.10/dist-packages/keras/src/engine/training.py\", line 2425, in step_function  **\n",
            "        outputs = model.distribute_strategy.run(run_step, args=(data,))\n",
            "    File \"/usr/local/lib/python3.10/dist-packages/keras/src/engine/training.py\", line 2413, in run_step  **\n",
            "        outputs = model.predict_step(data)\n",
            "    File \"/usr/local/lib/python3.10/dist-packages/keras/src/engine/training.py\", line 2381, in predict_step\n",
            "        return self(x, training=False)\n",
            "    File \"/usr/local/lib/python3.10/dist-packages/keras/src/utils/traceback_utils.py\", line 70, in error_handler\n",
            "        raise e.with_traceback(filtered_tb) from None\n",
            "    File \"/usr/local/lib/python3.10/dist-packages/keras/src/engine/input_spec.py\", line 235, in assert_input_compatibility\n",
            "        raise ValueError(\n",
            "\n",
            "    ValueError: Exception encountered when calling layer 'model' (type Functional).\n",
            "    \n",
            "    Input 0 of layer \"lstm\" is incompatible with the layer: expected ndim=3, found ndim=4. Full shape received: (None, 28, 28, 3)\n",
            "    \n",
            "    Call arguments received by layer 'model' (type Functional):\n",
            "      • inputs=tf.Tensor(shape=(None, 28, 28, 3), dtype=uint8)\n",
            "      • training=False\n",
            "      • mask=None\n",
            "\n",
            "2024-07-03 13:43:35.928 `label` got an empty value. This is discouraged for accessibility reasons and may be disallowed in the future by raising an exception. Please provide a non-empty label and hide it with label_visibility if needed.\n",
            "/content/fashion.py:18: DeprecationWarning: ANTIALIAS is deprecated and will be removed in Pillow 10 (2023-07-01). Use LANCZOS or Resampling.LANCZOS instead.\n",
            "  image=ImageOps.fit(image_data,size,Image.ANTIALIAS)\n",
            "2024-07-03 13:43:36.320 Uncaught app exception\n",
            "Traceback (most recent call last):\n",
            "  File \"/usr/local/lib/python3.10/dist-packages/streamlit/runtime/scriptrunner/script_runner.py\", line 589, in _run_script\n",
            "    exec(code, module.__dict__)\n",
            "  File \"/content/fashion.py\", line 33, in <module>\n",
            "    predictions=predict(image,model)\n",
            "  File \"/content/fashion.py\", line 22, in predict\n",
            "    prediction=model.predict(img_reshape)\n",
            "  File \"/usr/local/lib/python3.10/dist-packages/keras/src/utils/traceback_utils.py\", line 70, in error_handler\n",
            "    raise e.with_traceback(filtered_tb) from None\n",
            "  File \"/tmp/__autograph_generated_filefnm75z2s.py\", line 15, in tf__predict_function\n",
            "    retval_ = ag__.converted_call(ag__.ld(step_function), (ag__.ld(self), ag__.ld(iterator)), None, fscope)\n",
            "ValueError: in user code:\n",
            "\n",
            "    File \"/usr/local/lib/python3.10/dist-packages/keras/src/engine/training.py\", line 2440, in predict_function  *\n",
            "        return step_function(self, iterator)\n",
            "    File \"/usr/local/lib/python3.10/dist-packages/keras/src/engine/training.py\", line 2425, in step_function  **\n",
            "        outputs = model.distribute_strategy.run(run_step, args=(data,))\n",
            "    File \"/usr/local/lib/python3.10/dist-packages/keras/src/engine/training.py\", line 2413, in run_step  **\n",
            "        outputs = model.predict_step(data)\n",
            "    File \"/usr/local/lib/python3.10/dist-packages/keras/src/engine/training.py\", line 2381, in predict_step\n",
            "        return self(x, training=False)\n",
            "    File \"/usr/local/lib/python3.10/dist-packages/keras/src/utils/traceback_utils.py\", line 70, in error_handler\n",
            "        raise e.with_traceback(filtered_tb) from None\n",
            "    File \"/usr/local/lib/python3.10/dist-packages/keras/src/engine/input_spec.py\", line 235, in assert_input_compatibility\n",
            "        raise ValueError(\n",
            "\n",
            "    ValueError: Exception encountered when calling layer 'model' (type Functional).\n",
            "    \n",
            "    Input 0 of layer \"lstm\" is incompatible with the layer: expected ndim=3, found ndim=4. Full shape received: (None, 28, 28, 3)\n",
            "    \n",
            "    Call arguments received by layer 'model' (type Functional):\n",
            "      • inputs=tf.Tensor(shape=(None, 28, 28, 3), dtype=uint8)\n",
            "      • training=False\n",
            "      • mask=None\n",
            "\n",
            "2024-07-03 13:43:46.066 `label` got an empty value. This is discouraged for accessibility reasons and may be disallowed in the future by raising an exception. Please provide a non-empty label and hide it with label_visibility if needed.\n",
            "2024-07-03 13:43:59.086 `label` got an empty value. This is discouraged for accessibility reasons and may be disallowed in the future by raising an exception. Please provide a non-empty label and hide it with label_visibility if needed.\n",
            "2024-07-03 13:44:08.386 `label` got an empty value. This is discouraged for accessibility reasons and may be disallowed in the future by raising an exception. Please provide a non-empty label and hide it with label_visibility if needed.\n",
            "/content/fashion.py:18: DeprecationWarning: ANTIALIAS is deprecated and will be removed in Pillow 10 (2023-07-01). Use LANCZOS or Resampling.LANCZOS instead.\n",
            "  image=ImageOps.fit(image_data,size,Image.ANTIALIAS)\n",
            "2024-07-03 13:44:08.473 Uncaught app exception\n",
            "Traceback (most recent call last):\n",
            "  File \"/usr/local/lib/python3.10/dist-packages/streamlit/runtime/scriptrunner/script_runner.py\", line 589, in _run_script\n",
            "    exec(code, module.__dict__)\n",
            "  File \"/content/fashion.py\", line 33, in <module>\n",
            "    predictions=predict(image,model)\n",
            "  File \"/content/fashion.py\", line 22, in predict\n",
            "    prediction=model.predict(img_reshape)\n",
            "  File \"/usr/local/lib/python3.10/dist-packages/keras/src/utils/traceback_utils.py\", line 70, in error_handler\n",
            "    raise e.with_traceback(filtered_tb) from None\n",
            "  File \"/tmp/__autograph_generated_filefnm75z2s.py\", line 15, in tf__predict_function\n",
            "    retval_ = ag__.converted_call(ag__.ld(step_function), (ag__.ld(self), ag__.ld(iterator)), None, fscope)\n",
            "ValueError: in user code:\n",
            "\n",
            "    File \"/usr/local/lib/python3.10/dist-packages/keras/src/engine/training.py\", line 2440, in predict_function  *\n",
            "        return step_function(self, iterator)\n",
            "    File \"/usr/local/lib/python3.10/dist-packages/keras/src/engine/training.py\", line 2425, in step_function  **\n",
            "        outputs = model.distribute_strategy.run(run_step, args=(data,))\n",
            "    File \"/usr/local/lib/python3.10/dist-packages/keras/src/engine/training.py\", line 2413, in run_step  **\n",
            "        outputs = model.predict_step(data)\n",
            "    File \"/usr/local/lib/python3.10/dist-packages/keras/src/engine/training.py\", line 2381, in predict_step\n",
            "        return self(x, training=False)\n",
            "    File \"/usr/local/lib/python3.10/dist-packages/keras/src/utils/traceback_utils.py\", line 70, in error_handler\n",
            "        raise e.with_traceback(filtered_tb) from None\n",
            "    File \"/usr/local/lib/python3.10/dist-packages/keras/src/engine/input_spec.py\", line 235, in assert_input_compatibility\n",
            "        raise ValueError(\n",
            "\n",
            "    ValueError: Exception encountered when calling layer 'model' (type Functional).\n",
            "    \n",
            "    Input 0 of layer \"lstm\" is incompatible with the layer: expected ndim=3, found ndim=4. Full shape received: (None, 28, 28, 3)\n",
            "    \n",
            "    Call arguments received by layer 'model' (type Functional):\n",
            "      • inputs=tf.Tensor(shape=(None, 28, 28, 3), dtype=uint8)\n",
            "      • training=False\n",
            "      • mask=None\n",
            "\n",
            "2024-07-03 13:45:11.179 `label` got an empty value. This is discouraged for accessibility reasons and may be disallowed in the future by raising an exception. Please provide a non-empty label and hide it with label_visibility if needed.\n",
            "/content/fashion.py:18: DeprecationWarning: ANTIALIAS is deprecated and will be removed in Pillow 10 (2023-07-01). Use LANCZOS or Resampling.LANCZOS instead.\n",
            "  image=ImageOps.fit(image_data,size,Image.ANTIALIAS)\n",
            "2024-07-03 13:45:11.323 Uncaught app exception\n",
            "Traceback (most recent call last):\n",
            "  File \"/usr/local/lib/python3.10/dist-packages/streamlit/runtime/scriptrunner/script_runner.py\", line 589, in _run_script\n",
            "    exec(code, module.__dict__)\n",
            "  File \"/content/fashion.py\", line 33, in <module>\n",
            "    predictions=predict(image,model)\n",
            "  File \"/content/fashion.py\", line 22, in predict\n",
            "    prediction=model.predict(img_reshape)\n",
            "  File \"/usr/local/lib/python3.10/dist-packages/keras/src/utils/traceback_utils.py\", line 70, in error_handler\n",
            "    raise e.with_traceback(filtered_tb) from None\n",
            "  File \"/tmp/__autograph_generated_filefnm75z2s.py\", line 15, in tf__predict_function\n",
            "    retval_ = ag__.converted_call(ag__.ld(step_function), (ag__.ld(self), ag__.ld(iterator)), None, fscope)\n",
            "ValueError: in user code:\n",
            "\n",
            "    File \"/usr/local/lib/python3.10/dist-packages/keras/src/engine/training.py\", line 2440, in predict_function  *\n",
            "        return step_function(self, iterator)\n",
            "    File \"/usr/local/lib/python3.10/dist-packages/keras/src/engine/training.py\", line 2425, in step_function  **\n",
            "        outputs = model.distribute_strategy.run(run_step, args=(data,))\n",
            "    File \"/usr/local/lib/python3.10/dist-packages/keras/src/engine/training.py\", line 2413, in run_step  **\n",
            "        outputs = model.predict_step(data)\n",
            "    File \"/usr/local/lib/python3.10/dist-packages/keras/src/engine/training.py\", line 2381, in predict_step\n",
            "        return self(x, training=False)\n",
            "    File \"/usr/local/lib/python3.10/dist-packages/keras/src/utils/traceback_utils.py\", line 70, in error_handler\n",
            "        raise e.with_traceback(filtered_tb) from None\n",
            "    File \"/usr/local/lib/python3.10/dist-packages/keras/src/engine/input_spec.py\", line 235, in assert_input_compatibility\n",
            "        raise ValueError(\n",
            "\n",
            "    ValueError: Exception encountered when calling layer 'model' (type Functional).\n",
            "    \n",
            "    Input 0 of layer \"lstm\" is incompatible with the layer: expected ndim=3, found ndim=4. Full shape received: (None, 28, 28, 3)\n",
            "    \n",
            "    Call arguments received by layer 'model' (type Functional):\n",
            "      • inputs=tf.Tensor(shape=(None, 28, 28, 3), dtype=uint8)\n",
            "      • training=False\n",
            "      • mask=None\n",
            "\n",
            "2024-07-03 13:48:18.661 `label` got an empty value. This is discouraged for accessibility reasons and may be disallowed in the future by raising an exception. Please provide a non-empty label and hide it with label_visibility if needed.\n",
            "/content/fashion.py:18: DeprecationWarning: ANTIALIAS is deprecated and will be removed in Pillow 10 (2023-07-01). Use LANCZOS or Resampling.LANCZOS instead.\n",
            "  image=ImageOps.fit(image_data,size,Image.ANTIALIAS)\n",
            "2024-07-03 13:48:18.701 Uncaught app exception\n",
            "Traceback (most recent call last):\n",
            "  File \"/usr/local/lib/python3.10/dist-packages/streamlit/runtime/scriptrunner/script_runner.py\", line 589, in _run_script\n",
            "    exec(code, module.__dict__)\n",
            "  File \"/content/fashion.py\", line 33, in <module>\n",
            "    predictions=predict(image,model)\n",
            "  File \"/content/fashion.py\", line 22, in predict\n",
            "    prediction=model.predict(img_reshape)\n",
            "NameError: name 'img_reshape' is not defined\n",
            "2024-07-03 13:48:38.765 `label` got an empty value. This is discouraged for accessibility reasons and may be disallowed in the future by raising an exception. Please provide a non-empty label and hide it with label_visibility if needed.\n",
            "/content/fashion.py:18: DeprecationWarning: ANTIALIAS is deprecated and will be removed in Pillow 10 (2023-07-01). Use LANCZOS or Resampling.LANCZOS instead.\n",
            "  image=ImageOps.fit(image_data,size,Image.ANTIALIAS)\n",
            "2024-07-03 13:48:38.869 Uncaught app exception\n",
            "Traceback (most recent call last):\n",
            "  File \"/usr/local/lib/python3.10/dist-packages/streamlit/runtime/scriptrunner/script_runner.py\", line 589, in _run_script\n",
            "    exec(code, module.__dict__)\n",
            "  File \"/content/fashion.py\", line 33, in <module>\n",
            "    predictions=predict(image,model)\n",
            "  File \"/content/fashion.py\", line 22, in predict\n",
            "    prediction=model.predict(img)\n",
            "  File \"/usr/local/lib/python3.10/dist-packages/keras/src/utils/traceback_utils.py\", line 70, in error_handler\n",
            "    raise e.with_traceback(filtered_tb) from None\n",
            "  File \"/tmp/__autograph_generated_filefnm75z2s.py\", line 15, in tf__predict_function\n",
            "    retval_ = ag__.converted_call(ag__.ld(step_function), (ag__.ld(self), ag__.ld(iterator)), None, fscope)\n",
            "ValueError: in user code:\n",
            "\n",
            "    File \"/usr/local/lib/python3.10/dist-packages/keras/src/engine/training.py\", line 2440, in predict_function  *\n",
            "        return step_function(self, iterator)\n",
            "    File \"/usr/local/lib/python3.10/dist-packages/keras/src/engine/training.py\", line 2425, in step_function  **\n",
            "        outputs = model.distribute_strategy.run(run_step, args=(data,))\n",
            "    File \"/usr/local/lib/python3.10/dist-packages/keras/src/engine/training.py\", line 2413, in run_step  **\n",
            "        outputs = model.predict_step(data)\n",
            "    File \"/usr/local/lib/python3.10/dist-packages/keras/src/engine/training.py\", line 2381, in predict_step\n",
            "        return self(x, training=False)\n",
            "    File \"/usr/local/lib/python3.10/dist-packages/keras/src/utils/traceback_utils.py\", line 70, in error_handler\n",
            "        raise e.with_traceback(filtered_tb) from None\n",
            "    File \"/usr/local/lib/python3.10/dist-packages/keras/src/engine/input_spec.py\", line 298, in assert_input_compatibility\n",
            "        raise ValueError(\n",
            "\n",
            "    ValueError: Input 0 of layer \"model\" is incompatible with the layer: expected shape=(None, 28, 28), found shape=(None, 28, 3)\n",
            "\n",
            "2024-07-03 13:49:05.423 `label` got an empty value. This is discouraged for accessibility reasons and may be disallowed in the future by raising an exception. Please provide a non-empty label and hide it with label_visibility if needed.\n",
            "/content/fashion.py:18: DeprecationWarning: ANTIALIAS is deprecated and will be removed in Pillow 10 (2023-07-01). Use LANCZOS or Resampling.LANCZOS instead.\n",
            "  image=ImageOps.fit(image_data,size,Image.ANTIALIAS)\n",
            "2024-07-03 13:49:05.568 Uncaught app exception\n",
            "Traceback (most recent call last):\n",
            "  File \"/usr/local/lib/python3.10/dist-packages/streamlit/runtime/scriptrunner/script_runner.py\", line 589, in _run_script\n",
            "    exec(code, module.__dict__)\n",
            "  File \"/content/fashion.py\", line 33, in <module>\n",
            "    predictions=predict(image,model)\n",
            "  File \"/content/fashion.py\", line 22, in predict\n",
            "    prediction=model.predict(img)\n",
            "  File \"/usr/local/lib/python3.10/dist-packages/keras/src/utils/traceback_utils.py\", line 70, in error_handler\n",
            "    raise e.with_traceback(filtered_tb) from None\n",
            "  File \"/tmp/__autograph_generated_filefnm75z2s.py\", line 15, in tf__predict_function\n",
            "    retval_ = ag__.converted_call(ag__.ld(step_function), (ag__.ld(self), ag__.ld(iterator)), None, fscope)\n",
            "ValueError: in user code:\n",
            "\n",
            "    File \"/usr/local/lib/python3.10/dist-packages/keras/src/engine/training.py\", line 2440, in predict_function  *\n",
            "        return step_function(self, iterator)\n",
            "    File \"/usr/local/lib/python3.10/dist-packages/keras/src/engine/training.py\", line 2425, in step_function  **\n",
            "        outputs = model.distribute_strategy.run(run_step, args=(data,))\n",
            "    File \"/usr/local/lib/python3.10/dist-packages/keras/src/engine/training.py\", line 2413, in run_step  **\n",
            "        outputs = model.predict_step(data)\n",
            "    File \"/usr/local/lib/python3.10/dist-packages/keras/src/engine/training.py\", line 2381, in predict_step\n",
            "        return self(x, training=False)\n",
            "    File \"/usr/local/lib/python3.10/dist-packages/keras/src/utils/traceback_utils.py\", line 70, in error_handler\n",
            "        raise e.with_traceback(filtered_tb) from None\n",
            "    File \"/usr/local/lib/python3.10/dist-packages/keras/src/engine/input_spec.py\", line 298, in assert_input_compatibility\n",
            "        raise ValueError(\n",
            "\n",
            "    ValueError: Input 0 of layer \"model\" is incompatible with the layer: expected shape=(None, 28, 28), found shape=(None, 28, 3)\n",
            "\n",
            "2024-07-03 13:49:42.347 `label` got an empty value. This is discouraged for accessibility reasons and may be disallowed in the future by raising an exception. Please provide a non-empty label and hide it with label_visibility if needed.\n",
            "/content/fashion.py:18: DeprecationWarning: ANTIALIAS is deprecated and will be removed in Pillow 10 (2023-07-01). Use LANCZOS or Resampling.LANCZOS instead.\n",
            "  image=ImageOps.fit(image_data,size,Image.ANTIALIAS)\n",
            "2024-07-03 13:49:42.488 Uncaught app exception\n",
            "Traceback (most recent call last):\n",
            "  File \"/usr/local/lib/python3.10/dist-packages/streamlit/runtime/scriptrunner/script_runner.py\", line 589, in _run_script\n",
            "    exec(code, module.__dict__)\n",
            "  File \"/content/fashion.py\", line 33, in <module>\n",
            "    predictions=predict(image,model)\n",
            "  File \"/content/fashion.py\", line 22, in predict\n",
            "    prediction=model.predict(img)\n",
            "  File \"/usr/local/lib/python3.10/dist-packages/keras/src/utils/traceback_utils.py\", line 70, in error_handler\n",
            "    raise e.with_traceback(filtered_tb) from None\n",
            "  File \"/tmp/__autograph_generated_filefnm75z2s.py\", line 15, in tf__predict_function\n",
            "    retval_ = ag__.converted_call(ag__.ld(step_function), (ag__.ld(self), ag__.ld(iterator)), None, fscope)\n",
            "ValueError: in user code:\n",
            "\n",
            "    File \"/usr/local/lib/python3.10/dist-packages/keras/src/engine/training.py\", line 2440, in predict_function  *\n",
            "        return step_function(self, iterator)\n",
            "    File \"/usr/local/lib/python3.10/dist-packages/keras/src/engine/training.py\", line 2425, in step_function  **\n",
            "        outputs = model.distribute_strategy.run(run_step, args=(data,))\n",
            "    File \"/usr/local/lib/python3.10/dist-packages/keras/src/engine/training.py\", line 2413, in run_step  **\n",
            "        outputs = model.predict_step(data)\n",
            "    File \"/usr/local/lib/python3.10/dist-packages/keras/src/engine/training.py\", line 2381, in predict_step\n",
            "        return self(x, training=False)\n",
            "    File \"/usr/local/lib/python3.10/dist-packages/keras/src/utils/traceback_utils.py\", line 70, in error_handler\n",
            "        raise e.with_traceback(filtered_tb) from None\n",
            "    File \"/usr/local/lib/python3.10/dist-packages/keras/src/engine/input_spec.py\", line 298, in assert_input_compatibility\n",
            "        raise ValueError(\n",
            "\n",
            "    ValueError: Input 0 of layer \"model\" is incompatible with the layer: expected shape=(None, 28, 28), found shape=(None, 28, 3)\n",
            "\n",
            "2024-07-03 13:51:04.052 `label` got an empty value. This is discouraged for accessibility reasons and may be disallowed in the future by raising an exception. Please provide a non-empty label and hide it with label_visibility if needed.\n",
            "/content/fashion.py:18: DeprecationWarning: ANTIALIAS is deprecated and will be removed in Pillow 10 (2023-07-01). Use LANCZOS or Resampling.LANCZOS instead.\n",
            "  image=ImageOps.fit(image_data,size,Image.ANTIALIAS)\n",
            "2024-07-03 13:51:04.087 Uncaught app exception\n",
            "Traceback (most recent call last):\n",
            "  File \"/usr/local/lib/python3.10/dist-packages/streamlit/runtime/scriptrunner/script_runner.py\", line 589, in _run_script\n",
            "    exec(code, module.__dict__)\n",
            "  File \"/content/fashion.py\", line 33, in <module>\n",
            "    predictions=predict(image,model)\n",
            "  File \"/content/fashion.py\", line 21, in predict\n",
            "    img_reshape=img.reshape(())\n",
            "ValueError: cannot reshape array of size 2352 into shape ()\n",
            "2024-07-03 13:51:23.863 `label` got an empty value. This is discouraged for accessibility reasons and may be disallowed in the future by raising an exception. Please provide a non-empty label and hide it with label_visibility if needed.\n",
            "/content/fashion.py:18: DeprecationWarning: ANTIALIAS is deprecated and will be removed in Pillow 10 (2023-07-01). Use LANCZOS or Resampling.LANCZOS instead.\n",
            "  image=ImageOps.fit(image_data,size,Image.ANTIALIAS)\n",
            "2024-07-03 13:51:23.886 Uncaught app exception\n",
            "Traceback (most recent call last):\n",
            "  File \"/usr/local/lib/python3.10/dist-packages/streamlit/runtime/scriptrunner/script_runner.py\", line 589, in _run_script\n",
            "    exec(code, module.__dict__)\n",
            "  File \"/content/fashion.py\", line 33, in <module>\n",
            "    predictions=predict(image,model)\n",
            "  File \"/content/fashion.py\", line 21, in predict\n",
            "    img_reshape=img.reshape((1,28,28,1))\n",
            "ValueError: cannot reshape array of size 2352 into shape (1,28,28,1)\n",
            "2024-07-03 13:51:37.883 `label` got an empty value. This is discouraged for accessibility reasons and may be disallowed in the future by raising an exception. Please provide a non-empty label and hide it with label_visibility if needed.\n",
            "/content/fashion.py:18: DeprecationWarning: ANTIALIAS is deprecated and will be removed in Pillow 10 (2023-07-01). Use LANCZOS or Resampling.LANCZOS instead.\n",
            "  image=ImageOps.fit(image_data,size,Image.ANTIALIAS)\n",
            "2024-07-03 13:51:37.907 Uncaught app exception\n",
            "Traceback (most recent call last):\n",
            "  File \"/usr/local/lib/python3.10/dist-packages/streamlit/runtime/scriptrunner/script_runner.py\", line 589, in _run_script\n",
            "    exec(code, module.__dict__)\n",
            "  File \"/content/fashion.py\", line 33, in <module>\n",
            "    predictions=predict(image,model)\n",
            "  File \"/content/fashion.py\", line 21, in predict\n",
            "    img_reshape=img.reshape((1,28,28,1))\n",
            "ValueError: cannot reshape array of size 2352 into shape (1,28,28,1)\n",
            "2024-07-03 13:51:45.290 `label` got an empty value. This is discouraged for accessibility reasons and may be disallowed in the future by raising an exception. Please provide a non-empty label and hide it with label_visibility if needed.\n",
            "/content/fashion.py:18: DeprecationWarning: ANTIALIAS is deprecated and will be removed in Pillow 10 (2023-07-01). Use LANCZOS or Resampling.LANCZOS instead.\n",
            "  image=ImageOps.fit(image_data,size,Image.ANTIALIAS)\n",
            "2024-07-03 13:51:45.313 Uncaught app exception\n",
            "Traceback (most recent call last):\n",
            "  File \"/usr/local/lib/python3.10/dist-packages/streamlit/runtime/scriptrunner/script_runner.py\", line 589, in _run_script\n",
            "    exec(code, module.__dict__)\n",
            "  File \"/content/fashion.py\", line 33, in <module>\n",
            "    predictions=predict(image,model)\n",
            "  File \"/content/fashion.py\", line 21, in predict\n",
            "    img_reshape=img.reshape((1,28,28,1))\n",
            "ValueError: cannot reshape array of size 2352 into shape (1,28,28,1)\n",
            "2024-07-03 13:52:01.018 `label` got an empty value. This is discouraged for accessibility reasons and may be disallowed in the future by raising an exception. Please provide a non-empty label and hide it with label_visibility if needed.\n",
            "/content/fashion.py:18: DeprecationWarning: ANTIALIAS is deprecated and will be removed in Pillow 10 (2023-07-01). Use LANCZOS or Resampling.LANCZOS instead.\n",
            "  image=ImageOps.fit(image_data,size,Image.ANTIALIAS)\n",
            "2024-07-03 13:52:01.040 Uncaught app exception\n",
            "Traceback (most recent call last):\n",
            "  File \"/usr/local/lib/python3.10/dist-packages/streamlit/runtime/scriptrunner/script_runner.py\", line 589, in _run_script\n",
            "    exec(code, module.__dict__)\n",
            "  File \"/content/fashion.py\", line 33, in <module>\n",
            "    predictions=predict(image,model)\n",
            "  File \"/content/fashion.py\", line 21, in predict\n",
            "    img_reshape=img.reshape((28,28,1))\n",
            "ValueError: cannot reshape array of size 2352 into shape (28,28,1)\n",
            "2024-07-03 13:52:51.594 `label` got an empty value. This is discouraged for accessibility reasons and may be disallowed in the future by raising an exception. Please provide a non-empty label and hide it with label_visibility if needed.\n",
            "/content/fashion.py:18: DeprecationWarning: ANTIALIAS is deprecated and will be removed in Pillow 10 (2023-07-01). Use LANCZOS or Resampling.LANCZOS instead.\n",
            "  image=ImageOps.fit(image_data,size,Image.ANTIALIAS)\n",
            "2024-07-03 13:52:51.619 Uncaught app exception\n",
            "Traceback (most recent call last):\n",
            "  File \"/usr/local/lib/python3.10/dist-packages/streamlit/runtime/scriptrunner/script_runner.py\", line 589, in _run_script\n",
            "    exec(code, module.__dict__)\n",
            "  File \"/content/fashion.py\", line 34, in <module>\n",
            "    predictions=predict(image,model)\n",
            "  File \"/content/fashion.py\", line 22, in predict\n",
            "    img_reshape=img.reshape((28,28,1))\n",
            "ValueError: cannot reshape array of size 2352 into shape (28,28,1)\n",
            "2024-07-03 13:52:59.726 `label` got an empty value. This is discouraged for accessibility reasons and may be disallowed in the future by raising an exception. Please provide a non-empty label and hide it with label_visibility if needed.\n",
            "/content/fashion.py:18: DeprecationWarning: ANTIALIAS is deprecated and will be removed in Pillow 10 (2023-07-01). Use LANCZOS or Resampling.LANCZOS instead.\n",
            "  image=ImageOps.fit(image_data,size,Image.ANTIALIAS)\n",
            "2024-07-03 13:52:59.767 Uncaught app exception\n",
            "Traceback (most recent call last):\n",
            "  File \"/usr/local/lib/python3.10/dist-packages/streamlit/runtime/scriptrunner/script_runner.py\", line 589, in _run_script\n",
            "    exec(code, module.__dict__)\n",
            "  File \"/content/fashion.py\", line 34, in <module>\n",
            "    predictions=predict(image,model)\n",
            "  File \"/content/fashion.py\", line 22, in predict\n",
            "    img_reshape=img.reshape((28,28,1))\n",
            "ValueError: cannot reshape array of size 2352 into shape (28,28,1)\n",
            "2024-07-03 13:54:33.960 `label` got an empty value. This is discouraged for accessibility reasons and may be disallowed in the future by raising an exception. Please provide a non-empty label and hide it with label_visibility if needed.\n",
            "/content/fashion.py:18: DeprecationWarning: ANTIALIAS is deprecated and will be removed in Pillow 10 (2023-07-01). Use LANCZOS or Resampling.LANCZOS instead.\n",
            "  image=ImageOps.fit(image_data,size,Image.ANTIALIAS)\n",
            "2024-07-03 13:54:34.002 Uncaught app exception\n",
            "Traceback (most recent call last):\n",
            "  File \"/usr/local/lib/python3.10/dist-packages/streamlit/runtime/scriptrunner/script_runner.py\", line 589, in _run_script\n",
            "    exec(code, module.__dict__)\n",
            "  File \"/content/fashion.py\", line 34, in <module>\n",
            "    predictions=predict(image,model)\n",
            "  File \"/content/fashion.py\", line 22, in predict\n",
            "    img_reshape=img.reshape((128,28,1))\n",
            "ValueError: cannot reshape array of size 2352 into shape (128,28,1)\n",
            "2024-07-03 13:54:40.649 `label` got an empty value. This is discouraged for accessibility reasons and may be disallowed in the future by raising an exception. Please provide a non-empty label and hide it with label_visibility if needed.\n",
            "/content/fashion.py:18: DeprecationWarning: ANTIALIAS is deprecated and will be removed in Pillow 10 (2023-07-01). Use LANCZOS or Resampling.LANCZOS instead.\n",
            "  image=ImageOps.fit(image_data,size,Image.ANTIALIAS)\n",
            "2024-07-03 13:54:40.671 Uncaught app exception\n",
            "Traceback (most recent call last):\n",
            "  File \"/usr/local/lib/python3.10/dist-packages/streamlit/runtime/scriptrunner/script_runner.py\", line 589, in _run_script\n",
            "    exec(code, module.__dict__)\n",
            "  File \"/content/fashion.py\", line 34, in <module>\n",
            "    predictions=predict(image,model)\n",
            "  File \"/content/fashion.py\", line 22, in predict\n",
            "    img_reshape=img.reshape((1,28,28,1))\n",
            "ValueError: cannot reshape array of size 2352 into shape (1,28,28,1)\n",
            "2024-07-03 13:56:27.084 `label` got an empty value. This is discouraged for accessibility reasons and may be disallowed in the future by raising an exception. Please provide a non-empty label and hide it with label_visibility if needed.\n",
            "/content/fashion.py:18: DeprecationWarning: ANTIALIAS is deprecated and will be removed in Pillow 10 (2023-07-01). Use LANCZOS or Resampling.LANCZOS instead.\n",
            "  image=ImageOps.fit(image_data,size,Image.ANTIALIAS)\n",
            "2024-07-03 13:56:27.108 Uncaught app exception\n",
            "Traceback (most recent call last):\n",
            "  File \"/usr/local/lib/python3.10/dist-packages/streamlit/runtime/scriptrunner/script_runner.py\", line 589, in _run_script\n",
            "    exec(code, module.__dict__)\n",
            "  File \"/content/fashion.py\", line 34, in <module>\n",
            "    predictions=predict(image,model)\n",
            "  File \"/content/fashion.py\", line 20, in predict\n",
            "    img=cv2.cvtColor(image,cv2.COLOR_RGB2)\n",
            "AttributeError: module 'cv2' has no attribute 'COLOR_RGB2'\n",
            "2024-07-03 13:57:01.643 `label` got an empty value. This is discouraged for accessibility reasons and may be disallowed in the future by raising an exception. Please provide a non-empty label and hide it with label_visibility if needed.\n",
            "/content/fashion.py:18: DeprecationWarning: ANTIALIAS is deprecated and will be removed in Pillow 10 (2023-07-01). Use LANCZOS or Resampling.LANCZOS instead.\n",
            "  image=ImageOps.fit(image_data,size,Image.ANTIALIAS)\n",
            "2024-07-03 13:57:02.162035: I external/local_xla/xla/stream_executor/cuda/cuda_dnn.cc:454] Loaded cuDNN version 8906\n",
            "1/1 [==============================] - 1s 683ms/step\n",
            "2024-07-03 13:59:03.825 `label` got an empty value. This is discouraged for accessibility reasons and may be disallowed in the future by raising an exception. Please provide a non-empty label and hide it with label_visibility if needed.\n",
            "2024-07-03 13:59:22.236 `label` got an empty value. This is discouraged for accessibility reasons and may be disallowed in the future by raising an exception. Please provide a non-empty label and hide it with label_visibility if needed.\n",
            "/content/fashion.py:18: DeprecationWarning: ANTIALIAS is deprecated and will be removed in Pillow 10 (2023-07-01). Use LANCZOS or Resampling.LANCZOS instead.\n",
            "  image=ImageOps.fit(image_data,size,Image.ANTIALIAS)\n",
            "1/1 [==============================] - 0s 358ms/step\n",
            "2024-07-03 14:02:34.126 `label` got an empty value. This is discouraged for accessibility reasons and may be disallowed in the future by raising an exception. Please provide a non-empty label and hide it with label_visibility if needed.\n",
            "/content/fashion.py:18: DeprecationWarning: ANTIALIAS is deprecated and will be removed in Pillow 10 (2023-07-01). Use LANCZOS or Resampling.LANCZOS instead.\n",
            "  image=ImageOps.fit(image_data,size,Image.ANTIALIAS)\n",
            "1/1 [==============================] - 0s 349ms/step\n",
            "2024-07-03 14:04:29.896 `label` got an empty value. This is discouraged for accessibility reasons and may be disallowed in the future by raising an exception. Please provide a non-empty label and hide it with label_visibility if needed.\n",
            "2024-07-03 14:04:36.259 `label` got an empty value. This is discouraged for accessibility reasons and may be disallowed in the future by raising an exception. Please provide a non-empty label and hide it with label_visibility if needed.\n",
            "/content/fashion.py:18: DeprecationWarning: ANTIALIAS is deprecated and will be removed in Pillow 10 (2023-07-01). Use LANCZOS or Resampling.LANCZOS instead.\n",
            "  image=ImageOps.fit(image_data,size,Image.ANTIALIAS)\n",
            "1/1 [==============================] - 0s 345ms/step\n",
            "2024-07-03 14:06:06.743 `label` got an empty value. This is discouraged for accessibility reasons and may be disallowed in the future by raising an exception. Please provide a non-empty label and hide it with label_visibility if needed.\n",
            "2024-07-03 14:09:00.523 `label` got an empty value. This is discouraged for accessibility reasons and may be disallowed in the future by raising an exception. Please provide a non-empty label and hide it with label_visibility if needed.\n",
            "/content/fashion.py:18: DeprecationWarning: ANTIALIAS is deprecated and will be removed in Pillow 10 (2023-07-01). Use LANCZOS or Resampling.LANCZOS instead.\n",
            "  image=ImageOps.fit(image_data,size,Image.ANTIALIAS)\n",
            "WARNING:tensorflow:5 out of the last 5 calls to <function Model.make_predict_function.<locals>.predict_function at 0x7db6d48d17e0> triggered tf.function retracing. Tracing is expensive and the excessive number of tracings could be due to (1) creating @tf.function repeatedly in a loop, (2) passing tensors with different shapes, (3) passing Python objects instead of tensors. For (1), please define your @tf.function outside of the loop. For (2), @tf.function has reduce_retracing=True option that can avoid unnecessary retracing. For (3), please refer to https://www.tensorflow.org/guide/function#controlling_retracing and https://www.tensorflow.org/api_docs/python/tf/function for  more details.\n",
            "1/1 [==============================] - 0s 362ms/step\n",
            "2024-07-03 14:10:30.703 `label` got an empty value. This is discouraged for accessibility reasons and may be disallowed in the future by raising an exception. Please provide a non-empty label and hide it with label_visibility if needed.\n",
            "/content/fashion.py:18: DeprecationWarning: ANTIALIAS is deprecated and will be removed in Pillow 10 (2023-07-01). Use LANCZOS or Resampling.LANCZOS instead.\n",
            "  image=ImageOps.fit(image_data,size,Image.ANTIALIAS)\n",
            "WARNING:tensorflow:6 out of the last 6 calls to <function Model.make_predict_function.<locals>.predict_function at 0x7db644284310> triggered tf.function retracing. Tracing is expensive and the excessive number of tracings could be due to (1) creating @tf.function repeatedly in a loop, (2) passing tensors with different shapes, (3) passing Python objects instead of tensors. For (1), please define your @tf.function outside of the loop. For (2), @tf.function has reduce_retracing=True option that can avoid unnecessary retracing. For (3), please refer to https://www.tensorflow.org/guide/function#controlling_retracing and https://www.tensorflow.org/api_docs/python/tf/function for  more details.\n",
            "1/1 [==============================] - 0s 364ms/step\n",
            "2024-07-03 14:11:00.530 `label` got an empty value. This is discouraged for accessibility reasons and may be disallowed in the future by raising an exception. Please provide a non-empty label and hide it with label_visibility if needed.\n",
            "/content/fashion.py:18: DeprecationWarning: ANTIALIAS is deprecated and will be removed in Pillow 10 (2023-07-01). Use LANCZOS or Resampling.LANCZOS instead.\n",
            "  image=ImageOps.fit(image_data,size,Image.ANTIALIAS)\n",
            "1/1 [==============================] - 0s 461ms/step\n",
            "2024-07-03 14:11:11.242 `label` got an empty value. This is discouraged for accessibility reasons and may be disallowed in the future by raising an exception. Please provide a non-empty label and hide it with label_visibility if needed.\n",
            "/content/fashion.py:18: DeprecationWarning: ANTIALIAS is deprecated and will be removed in Pillow 10 (2023-07-01). Use LANCZOS or Resampling.LANCZOS instead.\n",
            "  image=ImageOps.fit(image_data,size,Image.ANTIALIAS)\n",
            "1/1 [==============================] - 0s 327ms/step\n",
            "2024-07-03 14:11:27.363 `label` got an empty value. This is discouraged for accessibility reasons and may be disallowed in the future by raising an exception. Please provide a non-empty label and hide it with label_visibility if needed.\n",
            "2024-07-03 14:11:35.414 `label` got an empty value. This is discouraged for accessibility reasons and may be disallowed in the future by raising an exception. Please provide a non-empty label and hide it with label_visibility if needed.\n",
            "/content/fashion.py:18: DeprecationWarning: ANTIALIAS is deprecated and will be removed in Pillow 10 (2023-07-01). Use LANCZOS or Resampling.LANCZOS instead.\n",
            "  image=ImageOps.fit(image_data,size,Image.ANTIALIAS)\n",
            "1/1 [==============================] - 0s 360ms/step\n",
            "2024-07-03 14:11:48.274 `label` got an empty value. This is discouraged for accessibility reasons and may be disallowed in the future by raising an exception. Please provide a non-empty label and hide it with label_visibility if needed.\n",
            "/content/fashion.py:18: DeprecationWarning: ANTIALIAS is deprecated and will be removed in Pillow 10 (2023-07-01). Use LANCZOS or Resampling.LANCZOS instead.\n",
            "  image=ImageOps.fit(image_data,size,Image.ANTIALIAS)\n",
            "1/1 [==============================] - 0s 350ms/step\n",
            "2024-07-03 14:12:19.899 `label` got an empty value. This is discouraged for accessibility reasons and may be disallowed in the future by raising an exception. Please provide a non-empty label and hide it with label_visibility if needed.\n",
            "/content/fashion.py:18: DeprecationWarning: ANTIALIAS is deprecated and will be removed in Pillow 10 (2023-07-01). Use LANCZOS or Resampling.LANCZOS instead.\n",
            "  image=ImageOps.fit(image_data,size,Image.ANTIALIAS)\n",
            "1/1 [==============================] - 0s 356ms/step\n",
            "2024-07-03 14:12:52.361 `label` got an empty value. This is discouraged for accessibility reasons and may be disallowed in the future by raising an exception. Please provide a non-empty label and hide it with label_visibility if needed.\n",
            "/content/fashion.py:18: DeprecationWarning: ANTIALIAS is deprecated and will be removed in Pillow 10 (2023-07-01). Use LANCZOS or Resampling.LANCZOS instead.\n",
            "  image=ImageOps.fit(image_data,size,Image.ANTIALIAS)\n",
            "1/1 [==============================] - 0s 351ms/step\n",
            "2024-07-03 14:13:03.621 `label` got an empty value. This is discouraged for accessibility reasons and may be disallowed in the future by raising an exception. Please provide a non-empty label and hide it with label_visibility if needed.\n",
            "/content/fashion.py:18: DeprecationWarning: ANTIALIAS is deprecated and will be removed in Pillow 10 (2023-07-01). Use LANCZOS or Resampling.LANCZOS instead.\n",
            "  image=ImageOps.fit(image_data,size,Image.ANTIALIAS)\n",
            "1/1 [==============================] - 0s 362ms/step\n",
            "2024-07-03 14:13:10.404 `label` got an empty value. This is discouraged for accessibility reasons and may be disallowed in the future by raising an exception. Please provide a non-empty label and hide it with label_visibility if needed.\n",
            "/content/fashion.py:18: DeprecationWarning: ANTIALIAS is deprecated and will be removed in Pillow 10 (2023-07-01). Use LANCZOS or Resampling.LANCZOS instead.\n",
            "  image=ImageOps.fit(image_data,size,Image.ANTIALIAS)\n",
            "1/1 [==============================] - 0s 492ms/step\n",
            "2024-07-03 14:13:45.603 `label` got an empty value. This is discouraged for accessibility reasons and may be disallowed in the future by raising an exception. Please provide a non-empty label and hide it with label_visibility if needed.\n",
            "/content/fashion.py:18: DeprecationWarning: ANTIALIAS is deprecated and will be removed in Pillow 10 (2023-07-01). Use LANCZOS or Resampling.LANCZOS instead.\n",
            "  image=ImageOps.fit(image_data,size,Image.ANTIALIAS)\n",
            "1/1 [==============================] - 1s 539ms/step\n",
            "2024-07-03 14:14:05.377 `label` got an empty value. This is discouraged for accessibility reasons and may be disallowed in the future by raising an exception. Please provide a non-empty label and hide it with label_visibility if needed.\n",
            "/content/fashion.py:18: DeprecationWarning: ANTIALIAS is deprecated and will be removed in Pillow 10 (2023-07-01). Use LANCZOS or Resampling.LANCZOS instead.\n",
            "  image=ImageOps.fit(image_data,size,Image.ANTIALIAS)\n",
            "1/1 [==============================] - 0s 358ms/step\n",
            "2024-07-03 14:15:03.613 `label` got an empty value. This is discouraged for accessibility reasons and may be disallowed in the future by raising an exception. Please provide a non-empty label and hide it with label_visibility if needed.\n",
            "/content/fashion.py:18: DeprecationWarning: ANTIALIAS is deprecated and will be removed in Pillow 10 (2023-07-01). Use LANCZOS or Resampling.LANCZOS instead.\n",
            "  image=ImageOps.fit(image_data,size,Image.ANTIALIAS)\n",
            "1/1 [==============================] - 0s 345ms/step\n",
            "2024-07-03 14:15:46.109 `label` got an empty value. This is discouraged for accessibility reasons and may be disallowed in the future by raising an exception. Please provide a non-empty label and hide it with label_visibility if needed.\n",
            "/content/fashion.py:18: DeprecationWarning: ANTIALIAS is deprecated and will be removed in Pillow 10 (2023-07-01). Use LANCZOS or Resampling.LANCZOS instead.\n",
            "  image=ImageOps.fit(image_data,size,Image.ANTIALIAS)\n",
            "1/1 [==============================] - 0s 355ms/step\n",
            "2024-07-03 14:16:23.408 `label` got an empty value. This is discouraged for accessibility reasons and may be disallowed in the future by raising an exception. Please provide a non-empty label and hide it with label_visibility if needed.\n",
            "/content/fashion.py:18: DeprecationWarning: ANTIALIAS is deprecated and will be removed in Pillow 10 (2023-07-01). Use LANCZOS or Resampling.LANCZOS instead.\n",
            "  image=ImageOps.fit(image_data,size,Image.ANTIALIAS)\n",
            "1/1 [==============================] - 0s 334ms/step\n",
            "2024-07-03 14:19:33.645 `label` got an empty value. This is discouraged for accessibility reasons and may be disallowed in the future by raising an exception. Please provide a non-empty label and hide it with label_visibility if needed.\n",
            "/content/fashion.py:18: DeprecationWarning: ANTIALIAS is deprecated and will be removed in Pillow 10 (2023-07-01). Use LANCZOS or Resampling.LANCZOS instead.\n",
            "  image=ImageOps.fit(image_data,size,Image.ANTIALIAS)\n",
            "1/1 [==============================] - 0s 342ms/step\n",
            "2024-07-03 14:19:34.037 Uncaught app exception\n",
            "Traceback (most recent call last):\n",
            "  File \"/usr/local/lib/python3.10/dist-packages/streamlit/runtime/scriptrunner/script_runner.py\", line 589, in _run_script\n",
            "    exec(code, module.__dict__)\n",
            "  File \"/content/fashion.py\", line 34, in <module>\n",
            "    score=tf.nn.le(predictions[0])\n",
            "AttributeError: module 'tensorflow._api.v2.nn' has no attribute 'le'\n",
            "2024-07-03 14:19:44.546 `label` got an empty value. This is discouraged for accessibility reasons and may be disallowed in the future by raising an exception. Please provide a non-empty label and hide it with label_visibility if needed.\n",
            "/content/fashion.py:18: DeprecationWarning: ANTIALIAS is deprecated and will be removed in Pillow 10 (2023-07-01). Use LANCZOS or Resampling.LANCZOS instead.\n",
            "  image=ImageOps.fit(image_data,size,Image.ANTIALIAS)\n",
            "1/1 [==============================] - 0s 370ms/step\n",
            "2024-07-03 14:19:45.004 Uncaught app exception\n",
            "Traceback (most recent call last):\n",
            "  File \"/usr/local/lib/python3.10/dist-packages/streamlit/runtime/scriptrunner/script_runner.py\", line 589, in _run_script\n",
            "    exec(code, module.__dict__)\n",
            "  File \"/content/fashion.py\", line 34, in <module>\n",
            "    score=tf.nn.leakyrelu(predictions[0])\n",
            "AttributeError: module 'tensorflow._api.v2.nn' has no attribute 'leakyrelu'\n",
            "2024-07-03 14:19:56.625 `label` got an empty value. This is discouraged for accessibility reasons and may be disallowed in the future by raising an exception. Please provide a non-empty label and hide it with label_visibility if needed.\n",
            "/content/fashion.py:18: DeprecationWarning: ANTIALIAS is deprecated and will be removed in Pillow 10 (2023-07-01). Use LANCZOS or Resampling.LANCZOS instead.\n",
            "  image=ImageOps.fit(image_data,size,Image.ANTIALIAS)\n",
            "1/1 [==============================] - 0s 369ms/step\n"
          ]
        }
      ]
    }
  ]
}